<?xml version="1.0" encoding="utf-8" ?>
<!-- =================================================================================== -->
<!-- |    This document was autogenerated by xacro from /home/dumabushitu/catkin_ws/src/vista_robot/vistar_description/urdf/vistar_with_topkinect.xacro | -->
<!-- |    EDITING THIS FILE BY HAND IS NOT RECOMMENDED                                 | -->
<!-- =================================================================================== -->
<robot name="vistar">
    <!-- THE ROBOT -->
    <link name="world" />
    <!--
  Author: Felix Messmer
-->
    <joint name="world_joint" type="fixed">
        <parent link="world" />
        <child link="base_link" />
        <origin rpy="0.0 0.0 0.0" xyz="0 0 1.05" />
    </joint>
    <!-- measured from model -->
    <link name="base_link">
        <visual>
            <geometry>
                <mesh filename="package://ur3_description/meshes/ur3/visual/base.dae" />
            </geometry>
            <material name="LightGrey">
                <color rgba="0.7 0.7 0.7 1.0" />
            </material>
        </visual>
        <collision>
            <geometry>
                <mesh filename="package://ur3_description/meshes/ur3/collision/base.stl" />
            </geometry>
        </collision>
        
<inertial>
            <mass value="2.0" />
            <origin rpy="0 0 0" xyz="0.0 0.0 0.0" />
            <inertia ixx="0.0030531654454" ixy="0.0" ixz="0.0" iyy="0.0030531654454" iyz="0.0" izz="0.005625" />
        </inertial>

    </link>
    <joint name="shoulder_pan_joint" type="revolute">
        <parent link="base_link" />
        <child link="shoulder_link" />
        <origin rpy="0.0 0.0 0.0" xyz="0.0 0.0 0.1519" />
        <axis xyz="0 0 1" />
        <limit effort="330.0" lower="-6.28318530718" upper="6.28318530718" velocity="2.16" />
        <dynamics damping="0.0" friction="0.0" />
    </joint>
    <link name="shoulder_link">
        <visual>
            <geometry>
                <mesh filename="package://ur3_description/meshes/ur3/visual/shoulder.dae" />
            </geometry>
            <material name="LightGrey">
                <color rgba="0.7 0.7 0.7 1.0" />
            </material>
        </visual>
        <collision>
            <geometry>
                <mesh filename="package://ur3_description/meshes/ur3/collision/shoulder.stl" />
            </geometry>
        </collision>
        
<inertial>
            <mass value="2.0" />
            <origin rpy="0 0 0" xyz="0.0 0.0 0.0" />
            <inertia ixx="0.0080931634294" ixy="0.0" ixz="0.0" iyy="0.0080931634294" iyz="0.0" izz="0.005625" />
        </inertial>

    </link>
    <joint name="shoulder_lift_joint" type="revolute">
        <parent link="shoulder_link" />
        <child link="upper_arm_link" />
        <origin rpy="0.0 1.57079632679 0.0" xyz="0.0 0.1198 0.0" />
        <axis xyz="0 1 0" />
        <limit effort="330.0" lower="-6.28318530718" upper="6.28318530718" velocity="2.16" />
        <dynamics damping="0.0" friction="0.0" />
    </joint>
    <link name="upper_arm_link">
        <visual>
            <geometry>
                <mesh filename="package://ur3_description/meshes/ur3/visual/upperarm.dae" />
            </geometry>
            <material name="LightGrey">
                <color rgba="0.7 0.7 0.7 1.0" />
            </material>
        </visual>
        <collision>
            <geometry>
                <mesh filename="package://ur3_description/meshes/ur3/collision/upperarm.stl" />
            </geometry>
        </collision>
        
<inertial>
            <mass value="3.42" />
            <origin rpy="0 0 0" xyz="0.0 0.0 0.121825" />
            <inertia ixx="0.0217284832211" ixy="0.0" ixz="0.0" iyy="0.0217284832211" iyz="0.0" izz="0.00961875" />
        </inertial>

    </link>
    <joint name="elbow_joint" type="revolute">
        <parent link="upper_arm_link" />
        <child link="forearm_link" />
        <origin rpy="0.0 0.0 0.0" xyz="0.0 -0.0925 0.24365" />
        <axis xyz="0 1 0" />
        <limit effort="150.0" lower="-3.14159265359" upper="3.14159265359" velocity="3.15" />
        <dynamics damping="0.0" friction="0.0" />
    </joint>
    <link name="forearm_link">
        <visual>
            <geometry>
                <mesh filename="package://ur3_description/meshes/ur3/visual/forearm.dae" />
            </geometry>
            <material name="LightGrey">
                <color rgba="0.7 0.7 0.7 1.0" />
            </material>
        </visual>
        <collision>
            <geometry>
                <mesh filename="package://ur3_description/meshes/ur3/collision/forearm.stl" />
            </geometry>
        </collision>
        
<inertial>
            <mass value="1.26" />
            <origin rpy="0 0 0" xyz="0.0 0.0 0.106625" />
            <inertia ixx="0.00654680644378" ixy="0.0" ixz="0.0" iyy="0.00654680644378" iyz="0.0" izz="0.00354375" />
        </inertial>

    </link>
    <joint name="wrist_1_joint" type="revolute">
        <parent link="forearm_link" />
        <child link="wrist_1_link" />
        <origin rpy="0.0 1.57079632679 0.0" xyz="0.0 0.0 0.21325" />
        <axis xyz="0 1 0" />
        <limit effort="54.0" lower="-6.28318530718" upper="6.28318530718" velocity="3.2" />
        <dynamics damping="0.0" friction="0.0" />
    </joint>
    <link name="wrist_1_link">
        <visual>
            <geometry>
                <mesh filename="package://ur3_description/meshes/ur3/visual/wrist1.dae" />
            </geometry>
            <material name="LightGrey">
                <color rgba="0.7 0.7 0.7 1.0" />
            </material>
        </visual>
        <collision>
            <geometry>
                <mesh filename="package://ur3_description/meshes/ur3/collision/wrist1.stl" />
            </geometry>
        </collision>
        
<inertial>
            <mass value="0.8" />
            <origin rpy="0 0 0" xyz="0.0 0.08505 0.0" />
            <inertia ixx="0.002084999166" ixy="0.0" ixz="0.0" iyy="0.002084999166" iyz="0.0" izz="0.00225" />
        </inertial>

    </link>
    <joint name="wrist_2_joint" type="revolute">
        <parent link="wrist_1_link" />
        <child link="wrist_2_link" />
        <origin rpy="0.0 0.0 0.0" xyz="0.0 0.08505 0.0" />
        <axis xyz="0 0 1" />
        <limit effort="54.0" lower="-6.28318530718" upper="6.28318530718" velocity="3.2" />
        <dynamics damping="0.0" friction="0.0" />
    </joint>
    <link name="wrist_2_link">
        <visual>
            <geometry>
                <mesh filename="package://ur3_description/meshes/ur3/visual/wrist2.dae" />
            </geometry>
            <material name="LightGrey">
                <color rgba="0.7 0.7 0.7 1.0" />
            </material>
        </visual>
        <collision>
            <geometry>
                <mesh filename="package://ur3_description/meshes/ur3/collision/wrist2.stl" />
            </geometry>
        </collision>
        
<inertial>
            <mass value="0.8" />
            <origin rpy="0 0 0" xyz="0.0 0.0 0.08535" />
            <inertia ixx="0.002084999166" ixy="0.0" ixz="0.0" iyy="0.002084999166" iyz="0.0" izz="0.00225" />
        </inertial>

    </link>
    <joint name="wrist_3_joint" type="revolute">
        <parent link="wrist_2_link" />
        <child link="wrist_3_link" />
        <origin rpy="0.0 0.0 0.0" xyz="0.0 0.0 0.08535" />
        <axis xyz="0 1 0" />
        <limit effort="54.0" lower="-6.28318530718" upper="6.28318530718" velocity="3.2" />
        <dynamics damping="0.0" friction="0.0" />
    </joint>
    <link name="wrist_3_link">
        <visual>
            <geometry>
                <mesh filename="package://ur3_description/meshes/ur3/visual/wrist3.dae" />
            </geometry>
            <material name="LightGrey">
                <color rgba="0.7 0.7 0.7 1.0" />
            </material>
        </visual>
        <collision>
            <geometry>
                <mesh filename="package://ur3_description/meshes/ur3/collision/wrist3.stl" />
            </geometry>
        </collision>
        
<inertial>
            <mass value="0.35" />
            <origin rpy="1.57079632679 0 0" xyz="0.0 0.0619 0.0" />
            <inertia ixx="0.00013626661216" ixy="0.0" ixz="0.0" iyy="0.00013626661216" iyz="0.0" izz="0.0001792" />
        </inertial>

    </link>
    <joint name="ee_fixed_joint" type="fixed">
        <parent link="wrist_3_link" />
        <child link="ee_link" />
        <origin rpy="0.0 0.0 1.57079632679" xyz="0.0 0.0819 0.0" />
    </joint>
    <link name="ee_link">
        <collision>
            <geometry>
                <box size="0.01 0.01 0.01" />
            </geometry>
            <origin rpy="0 0 0" xyz="-0.01 0 0" />
        </collision>
        
<inertial>
            <mass value="0.1" />
            <inertia ixx="0.03" iyy="0.03" izz="0.03" ixy="0.0" ixz="0.0" iyz="0.0" />
        </inertial>

    </link>
    <transmission name="shoulder_pan_trans">
        <type>transmission_interface/SimpleTransmission</type>
        <joint name="shoulder_pan_joint">
            <hardwareInterface>hardware_interface/PositionJointInterface</hardwareInterface>
        </joint>
        <actuator name="shoulder_pan_motor">
            <mechanicalReduction>1</mechanicalReduction>
        </actuator>
    </transmission>
    <transmission name="shoulder_lift_trans">
        <type>transmission_interface/SimpleTransmission</type>
        <joint name="shoulder_lift_joint">
            <hardwareInterface>hardware_interface/PositionJointInterface</hardwareInterface>
        </joint>
        <actuator name="shoulder_lift_motor">
            <mechanicalReduction>1</mechanicalReduction>
        </actuator>
    </transmission>
    <transmission name="elbow_trans">
        <type>transmission_interface/SimpleTransmission</type>
        <joint name="elbow_joint">
            <hardwareInterface>hardware_interface/PositionJointInterface</hardwareInterface>
        </joint>
        <actuator name="elbow_motor">
            <mechanicalReduction>1</mechanicalReduction>
        </actuator>
    </transmission>
    <transmission name="wrist_1_trans">
        <type>transmission_interface/SimpleTransmission</type>
        <joint name="wrist_1_joint">
            <hardwareInterface>hardware_interface/PositionJointInterface</hardwareInterface>
        </joint>
        <actuator name="wrist_1_motor">
            <mechanicalReduction>1</mechanicalReduction>
        </actuator>
    </transmission>
    <transmission name="wrist_2_trans">
        <type>transmission_interface/SimpleTransmission</type>
        <joint name="wrist_2_joint">
            <hardwareInterface>hardware_interface/PositionJointInterface</hardwareInterface>
        </joint>
        <actuator name="wrist_2_motor">
            <mechanicalReduction>1</mechanicalReduction>
        </actuator>
    </transmission>
    <transmission name="wrist_3_trans">
        <type>transmission_interface/SimpleTransmission</type>
        <joint name="wrist_3_joint">
            <hardwareInterface>hardware_interface/PositionJointInterface</hardwareInterface>
        </joint>
        <actuator name="wrist_3_motor">
            <mechanicalReduction>1</mechanicalReduction>
        </actuator>
    </transmission>
    <gazebo reference="shoulder_link">
        <selfCollide>true</selfCollide>
    </gazebo>
    <gazebo reference="upper_arm_link">
        <selfCollide>true</selfCollide>
    </gazebo>
    <gazebo reference="forearm_link">
        <selfCollide>true</selfCollide>
    </gazebo>
    <gazebo reference="wrist_1_link">
        <selfCollide>true</selfCollide>
    </gazebo>
    <gazebo reference="wrist_3_link">
        <selfCollide>true</selfCollide>
    </gazebo>
    <gazebo reference="wrist_2_link">
        <selfCollide>true</selfCollide>
    </gazebo>
    <gazebo reference="ee_link">
        <selfCollide>true</selfCollide>
    </gazebo>
    <!-- ROS base_link to UR 'Base' Coordinates transform -->
    <link name="base" />
    <joint name="base_link-base_fixed_joint" type="fixed">
        <!-- NOTE: this rotation is only needed as long as base_link itself is
                 not corrected wrt the real robot (ie: rotated over 180
                 degrees)
      -->
        <origin rpy="0 0 -3.14159265359" xyz="0 0 0" />
        <parent link="base_link" />
        <child link="base" />
    </joint>
    <!-- Frame coincident with all-zeros TCP on UR controller -->
    <link name="tool0" />
    <joint name="wrist_3_link-tool0_fixed_joint" type="fixed">
        <origin rpy="-1.57079632679 0 0" xyz="0 0.0819 0" />
        <parent link="wrist_3_link" />
        <child link="tool0" />
    </joint>
    <!-- base -->
    <joint name="tool0_gripper_base_joint" type="fixed">
        <origin rpy="0 0 1.57079632679" xyz="0 0 0" />
        <parent link="tool0" />
        <child link="gripper_base" />
    </joint>
    <link name="gripper_base">
        
<inertial>
            <mass value="0.5" />
            <origin xyz="0 0 0.0075" />
            <inertia ixx="0.284375" ixy="0" ixz="0" iyy="0.284375" iyz="0" izz="0.4" />
        </inertial>

        <visual>
            <origin rpy="0 -1.5708 0" xyz="0 0 0" />
            <geometry>
                <mesh filename="package://robotiq_2f_85_gripper_description/meshes/visual/base.dae" />
            </geometry>
        </visual>
        <collision>
            <geometry>
                <mesh filename="package://robotiq_2f_85_gripper_description/meshes/collision/base.stl" scale="0.001 0.001 0.001" />
            </geometry>
        </collision>
    </link>
    <!-- right finger -->
    <joint name="gripper_right_driver_joint" type="revolute">
        <origin rpy="0 0 0" xyz="0 0.0306011 0.054904" />
        <parent link="gripper_base" />
        <child link="gripper_right_driver" />
        <axis xyz="1 0 0" />
        <limit effort="60" lower="0.0" upper="0.872664444444" velocity="1.91986177778" />
    </joint>
    <link name="gripper_right_driver">
        
<inertial>
            <mass value="0.1" />
            <origin rpy="0 0 0" xyz="0 0.02 0" />
            <inertia ixx="0.0166666666667" ixy="0" ixz="0" iyy="0.00666666666667" iyz="0" izz="0.0166666666667" />
        </inertial>

        <visual>
            <geometry>
                <mesh filename="package://robotiq_2f_85_gripper_description/meshes/visual/driver.dae" scale="0.001 0.001 0.001" />
            </geometry>
        </visual>
        <collision>
            <geometry>
                <mesh filename="package://robotiq_2f_85_gripper_description/meshes/collision/driver.stl" scale="0.001 0.001 0.001" />
            </geometry>
        </collision>
    </link>
    <joint name="gripper_right_coupler_joint" type="fixed">
        <origin rpy="0 0 0" xyz="0 0.0315 -0.0041" />
        <parent link="gripper_right_driver" />
        <child link="gripper_right_coupler" />
    </joint>
    <link name="gripper_right_coupler">
        
<inertial>
            <mass value="0.1" />
            <origin rpy="-1.7 0 0" xyz="0 0.0 0.025" />
            <inertia ixx="0.0385416666667" ixy="0" ixz="0" iyy="0.0108333333333" iyz="0" izz="0.0427083333333" />
        </inertial>

        <visual>
            <geometry>
                <mesh filename="package://robotiq_2f_85_gripper_description/meshes/visual/coupler.dae" scale="0.001 0.001 0.001" />
            </geometry>
        </visual>
        <collision>
            <geometry>
                <mesh filename="package://robotiq_2f_85_gripper_description/meshes/collision/coupler.stl" scale="0.001 0.001 0.001" />
            </geometry>
        </collision>
    </link>
    <joint name="gripper_right_follower_joint" type="revolute">
        <origin rpy="0 0 0" xyz="0 0.0061 0.0471" />
        <parent link="gripper_right_coupler" />
        <child link="gripper_right_follower" />
        <axis xyz="1 0 0" />
        <limit effort="176" lower="-2.96705911111" upper="2.96705911111" velocity="1.91986177778" />
        <mimic joint="gripper_right_driver_joint" multiplier="-1" />
    </joint>
    <link name="gripper_right_follower">
        
<inertial>
            <mass value="0.1" />
            <origin xyz="0 -0.018 0.022" />
            <inertia ixx="0.021075" ixy="0" ixz="0" iyy="0.0225333333333" iyz="0" izz="0.00520833333333" />
        </inertial>

        <visual>
            <geometry>
                <mesh filename="package://robotiq_2f_85_gripper_description/meshes/visual/follower.dae" scale="0.001 0.001 0.001" />
            </geometry>
        </visual>
        <collision>
            <geometry>
                <mesh filename="package://robotiq_2f_85_gripper_description/meshes/collision/follower.stl" scale="0.001 0.001 0.001" />
            </geometry>
        </collision>
    </link>
    <joint name="gripper_right_pad_joint" type="fixed">
        <parent link="gripper_right_follower" />
        <child link="gripper_right_pad" />
    </joint>
    <link name="gripper_right_pad">
        
<inertial>
            <mass value="0.1" />
            <origin xyz="0 -0.022 0.031" />
            <inertia ixx="0.0113333333333" ixy="0" ixz="0" iyy="0.0141333333333" iyz="0" izz="0.00386666666667" />
        </inertial>

        <visual>
            <geometry>
                <mesh filename="package://robotiq_2f_85_gripper_description/meshes/visual/pad.dae" scale="0.001 0.001 0.001" />
            </geometry>
        </visual>
        <collision>
            <geometry>
                <mesh filename="package://robotiq_2f_85_gripper_description/meshes/collision/pad.stl" scale="0.001 0.001 0.001" />
            </geometry>
        </collision>
    </link>
    <joint name="gripper_right_spring_link_joint" type="revolute">
        <origin rpy="0 0 0" xyz="0 0.012 0.0614" />
        <parent link="gripper_base" />
        <child link="gripper_right_spring_link" />
        <axis xyz="1 0 0" />
        <limit effort="176" lower="-2.96705911111" upper="2.96705911111" velocity="1.91986177778" />
        <mimic joint="gripper_right_driver_joint" multiplier="1" />
    </joint>
    <link name="gripper_right_spring_link">
        
<inertial>
            <mass value="0.1" />
            <origin rpy="-0.7068 0 0" xyz="0 0.018 0.018" />
            <inertia ixx="0.0385416666667" ixy="0" ixz="0" iyy="0.0485416666667" iyz="0" izz="0.0166666666667" />
        </inertial>

        <visual>
            <geometry>
                <mesh filename="package://robotiq_2f_85_gripper_description/meshes/visual/spring_link.dae" scale="0.001 0.001 0.001" />
            </geometry>
        </visual>
        <collision>
            <geometry>
                <mesh filename="package://robotiq_2f_85_gripper_description/meshes/collision/spring_link.stl" scale="0.001 0.001 0.001" />
            </geometry>
        </collision>
    </link>
    <!-- left finger -->
    <joint name="gripper_left_driver_joint" type="revolute">
        <origin rpy="0 0 3.141592653589793" xyz="0 -0.0306011 0.054904" />
        <parent link="gripper_base" />
        <child link="gripper_left_driver" />
        <axis xyz="1 0 0" />
        <limit effort="176" lower="0.0" upper="0.872664444444" velocity="1.91986177778" />
        <mimic joint="gripper_right_driver_joint" multiplier="1" />
    </joint>
    <link name="gripper_left_driver">
        
<inertial>
            <mass value="0.1" />
            <origin rpy="0 0 0" xyz="0 0.02 0" />
            <inertia ixx="0.0166666666667" ixy="0" ixz="0" iyy="0.00666666666667" iyz="0" izz="0.0166666666667" />
        </inertial>

        <visual>
            <geometry>
                <mesh filename="package://robotiq_2f_85_gripper_description/meshes/visual/driver.dae" scale="0.001 0.001 0.001" />
            </geometry>
        </visual>
        <collision>
            <geometry>
                <mesh filename="package://robotiq_2f_85_gripper_description/meshes/collision/driver.stl" scale="0.001 0.001 0.001" />
            </geometry>
        </collision>
    </link>
    <joint name="gripper_left_coupler_joint" type="fixed">
        <origin rpy="0 0 0" xyz="0 0.0315 -0.0041" />
        <parent link="gripper_left_driver" />
        <child link="gripper_left_coupler" />
    </joint>
    <link name="gripper_left_coupler">
        
<inertial>
            <mass value="0.1" />
            <origin rpy="-1.7 0 0" xyz="0 0.0 0.025" />
            <inertia ixx="0.0385416666667" ixy="0" ixz="0" iyy="0.0108333333333" iyz="0" izz="0.0427083333333" />
        </inertial>

        <visual>
            <geometry>
                <mesh filename="package://robotiq_2f_85_gripper_description/meshes/visual/coupler.dae" scale="0.001 0.001 0.001" />
            </geometry>
        </visual>
        <collision>
            <geometry>
                <mesh filename="package://robotiq_2f_85_gripper_description/meshes/collision/coupler.stl" scale="0.001 0.001 0.001" />
            </geometry>
        </collision>
    </link>
    <joint name="gripper_left_follower_joint" type="revolute">
        <origin rpy="0 0 0" xyz="0 0.0061 0.0471" />
        <parent link="gripper_left_coupler" />
        <child link="gripper_left_follower" />
        <axis xyz="1 0 0" />
        <limit effort="176" lower="-2.96705911111" upper="2.96705911111" velocity="1.91986177778" />
        <mimic joint="gripper_right_driver_joint" multiplier="-1" />
    </joint>
    <link name="gripper_left_follower">
        
<inertial>
            <mass value="0.1" />
            <origin xyz="0 -0.018 0.022" />
            <inertia ixx="0.021075" ixy="0" ixz="0" iyy="0.0225333333333" iyz="0" izz="0.00520833333333" />
        </inertial>

        <visual>
            <geometry>
                <mesh filename="package://robotiq_2f_85_gripper_description/meshes/visual/follower.dae" scale="0.001 0.001 0.001" />
            </geometry>
        </visual>
        <collision>
            <geometry>
                <mesh filename="package://robotiq_2f_85_gripper_description/meshes/collision/follower.stl" scale="0.001 0.001 0.001" />
            </geometry>
        </collision>
    </link>
    <joint name="gripper_left_pad_joint" type="fixed">
        <parent link="gripper_left_follower" />
        <child link="gripper_left_pad" />
    </joint>
    <link name="gripper_left_pad">
        
<inertial>
            <mass value="0.1" />
            <origin xyz="0 -0.022 0.031" />
            <inertia ixx="0.0113333333333" ixy="0" ixz="0" iyy="0.0141333333333" iyz="0" izz="0.00386666666667" />
        </inertial>

        <visual>
            <geometry>
                <mesh filename="package://robotiq_2f_85_gripper_description/meshes/visual/pad.dae" scale="0.001 0.001 0.001" />
            </geometry>
        </visual>
        <collision>
            <geometry>
                <mesh filename="package://robotiq_2f_85_gripper_description/meshes/collision/pad.stl" scale="0.001 0.001 0.001" />
            </geometry>
        </collision>
    </link>
    <joint name="gripper_left_spring_link_joint" type="revolute">
        <origin rpy="0 0 3.141592653589793" xyz="0 -0.012 0.0614" />
        <parent link="gripper_base" />
        <child link="gripper_left_spring_link" />
        <axis xyz="1 0 0" />
        <limit effort="176" lower="-2.96705911111" upper="2.96705911111" velocity="1.91986177778" />
        <mimic joint="gripper_right_driver_joint" multiplier="1" />
    </joint>
    <link name="gripper_left_spring_link">
        
<inertial>
            <mass value="0.1" />
            <origin rpy="-0.7068 0 0" xyz="0 0.018 0.018" />
            <inertia ixx="0.0385416666667" ixy="0" ixz="0" iyy="0.0485416666667" iyz="0" izz="0.0166666666667" />
        </inertial>

        <visual>
            <geometry>
                <mesh filename="package://robotiq_2f_85_gripper_description/meshes/visual/spring_link.dae" scale="0.001 0.001 0.001" />
            </geometry>
        </visual>
        <collision>
            <geometry>
                <mesh filename="package://robotiq_2f_85_gripper_description/meshes/collision/spring_link.stl" scale="0.001 0.001 0.001" />
            </geometry>
        </collision>
    </link>
    <transmission name="gripper_right_driver_trans">
        <type>transmission_interface/SimpleTransmission</type>
        <joint name="gripper_right_driver_joint">
            <hardwareInterface>hardware_interface/PositionJointInterface</hardwareInterface>
        </joint>
        <actuator name="gripper_right_driver_motor">
            <mechanicalReduction>1</mechanicalReduction>
        </actuator>
    </transmission>
    <gazebo>
        <plugin filename="libroboticsgroup_gazebo_mimic_joint_plugin.so" name="gripper_right_follower_joint_plugin">
            <joint>gripper_right_driver_joint</joint>
            <mimicJoint>gripper_right_follower_joint</mimicJoint>
            <multiplier>-1</multiplier>
        </plugin>
        <plugin filename="libroboticsgroup_gazebo_mimic_joint_plugin.so" name="gripper_right_spring_link_joint_plugin">
            <joint>gripper_right_driver_joint</joint>
            <mimicJoint>gripper_right_spring_link_joint</mimicJoint>
            <multiplier>1</multiplier>
        </plugin>
        <plugin filename="libroboticsgroup_gazebo_mimic_joint_plugin.so" name="gripper_left_follower_joint_plugin">
            <joint>gripper_right_driver_joint</joint>
            <mimicJoint>gripper_left_follower_joint</mimicJoint>
            <multiplier>-1</multiplier>
        </plugin>
        <plugin filename="libroboticsgroup_gazebo_mimic_joint_plugin.so" name="gripper_left_spring_link_joint_plugin">
            <joint>gripper_right_driver_joint</joint>
            <mimicJoint>gripper_left_spring_link_joint</mimicJoint>
            <multiplier>1</multiplier>
        </plugin>
        <plugin filename="libroboticsgroup_gazebo_mimic_joint_plugin.so" name="gripper_left_driver_joint_plugin">
            <joint>gripper_right_driver_joint</joint>
            <mimicJoint>gripper_left_driver_joint</mimicJoint>
            <multiplier>1</multiplier>
        </plugin>
    </gazebo>
    <gazebo reference="gripper_right_pad">
        <implicitSpringDamper>1</implicitSpringDamper>
        <mu1>100000</mu1>
        <mu2>100000</mu2>
        <kp>100000000.0</kp>
        <kd>1.0</kd>
    </gazebo>
    <gazebo reference="gripper_left_pad">
        <implicitSpringDamper>1</implicitSpringDamper>
        <mu1>100000</mu1>
        <mu2>100000</mu2>
        <kp>100000000.0</kp>
        <kd>1.0</kd>
    </gazebo>
    <joint name="base_link_camera_base_joint" type="fixed">
        <origin rpy="0 0.628318530718 -1.57079632679" xyz="0 1.1 0.5" />
        <parent link="base_link" />
        <child link="camera_link" />
    </joint>
    <!-- Create kinect reference frame -->
    <!-- Add mesh for kinect -->
    <link name="camera_link">
        <origin rpy="0 0 0" xyz="0 0 0" />
        <visual>
            <origin rpy="0 0 1.57079632679" xyz="0 0 0" />
            <geometry>
                <mesh filename="package://vistar_gazebo/models/kinect/meshes/kinect.dae" />
            </geometry>
        </visual>
        <collision>
            <geometry>
                <box size="0.07 0.3 0.09" />
            </geometry>
        </collision>
        
<inertial>
            <mass value="0.1" />
            <inertia ixx="0.03" iyy="0.03" izz="0.03" ixy="0.0" ixz="0.0" iyz="0.0" />
        </inertial>

    </link>
    <joint name="camera_optical_joint" type="fixed">
        <origin rpy="-1.5708 0 -1.5708" xyz="0 0 0" />
        <parent link="camera_link" />
        <child link="camera_frame_optical" />
    </joint>
    <link name="camera_frame_optical" />
    <gazebo reference="camera_link">
        <sensor name="camera" type="depth">
            <always_on>true</always_on>
            <update_rate>20.0</update_rate>
            <camera>
                <horizontal_fov>1.0471975512</horizontal_fov>
                <image>
                    <format>R8G8B8</format>
                    <width>640</width>
                    <height>480</height>
                </image>
                <clip>
                    <near>0.05</near>
                    <far>8.0</far>
                </clip>
            </camera>
            <plugin filename="libgazebo_ros_openni_kinect.so" name="kinect_camera_controller">
                <cameraName>camera</cameraName>
                <alwaysOn>true</alwaysOn>
                <updateRate>10</updateRate>
                <imageTopicName>rgb/image_raw</imageTopicName>
                <depthImageTopicName>depth/image_raw</depthImageTopicName>
                <pointCloudTopicName>depth/points</pointCloudTopicName>
                <cameraInfoTopicName>rgb/camera_info</cameraInfoTopicName>
                <depthImageCameraInfoTopicName>depth/camera_info</depthImageCameraInfoTopicName>
                <frameName>camera_frame_optical</frameName>
                <baseline>0.1</baseline>
                <distortion_k1>0.0</distortion_k1>
                <distortion_k2>0.0</distortion_k2>
                <distortion_k3>0.0</distortion_k3>
                <distortion_t1>0.0</distortion_t1>
                <distortion_t2>0.0</distortion_t2>
                <pointCloudCutoff>0.4</pointCloudCutoff>
            </plugin>
        </sensor>
    </gazebo>
    <!-- Plugin -->
    <gazebo>
        <plugin filename="libgazebo_ros_control.so" name="ros_control">
            <!--robotNamespace>/</robotNamespace-->
            <!--robotSimType>gazebo_ros_control/DefaultRobotHWSim</robotSimType-->
        </plugin>
    </gazebo>
</robot>
